<?xml version="1.0"?>
<robot name="oneleg">

  <material name="blue">
    <color rgba="0 0 0.8 1"/>
  </material>
  <material name="black">
    <color rgba="0 0 0 1"/>
  </material>
  <material name="white">
    <color rgba="1 1 1 1"/>
  </material>
  
  <link name="base_link">
    <visual>
      <geometry>
        <cylinder length="0.045" radius="0.0127"/>
      </geometry>
      <origin rpy="0 0 0" xyz="0 0 0.0"/>   
      <material name="blue"/>
    </visual>
    <collision>
      <geometry>
        <cylinder length="0.045" radius="0.0127"/>
      </geometry>
      <origin rpy="0 0 0" xyz="0 0 0.0"/>   
      <material name="blue"/>
    </collision>    
    <inertial>
      <mass value="0.03"/>
      <inertia ixx="0.4" ixy="0.0" ixz="0.0" iyy="0.4" iyz="0.0" izz="0.2"/>
    </inertial>
  </link>

  
  <link name="thigh_link">
    <visual>
      <geometry>
        <box size="0.15 0.035 0.006"/>
      </geometry>
      <material name="white"/>
      <origin rpy="0 0 0" xyz="0.0623 0 0"/>   
    </visual>
    <collision>
      <geometry>
        <box size="0.15 0.035 0.006"/>
      </geometry>
      <material name="white"/>
      <origin rpy="0 0 0" xyz="0.0623 0 0"/>   
    </collision>
    <inertial>
      <mass value="0.03"/>
      <inertia ixx="0.4" ixy="0.0" ixz="0.0" iyy="0.4" iyz="0.0" izz="0.2"/>
    </inertial>
  </link>
  
    <link name="leg_link">
    <visual>
      <geometry>
        <cylinder length="0.14" radius="0.0127"/>
      </geometry>
      <material name="white"/>
      <origin rpy="0 0 0" xyz="0 0 -0.06"/>   
    </visual>
    <collision>
      <geometry>
        <cylinder length="0.14" radius="0.0127"/>
      </geometry>
      <material name="white"/>
      <origin rpy="0 0 0" xyz="0 0 -0.06"/>   
    </collision>    
    <inertial>
      <mass value="0.03"/>
      <inertia ixx="0.4" ixy="0.0" ixz="0.0" iyy="0.4" iyz="0.0" izz="0.2"/>
    </inertial>    
  </link>

  <joint name="hip_to_thigh" type="revolute">
    <parent link="base_link"/>
    <child link="thigh_link"/>
    <origin xyz="0 0 -0.03"/>
    <axis xyz="0 1 0"/>
    <limit effort="1000.0" lower="-0.785" upper="0.785" velocity="0.5"/>    
  </joint>

  <joint name="thigh_to_leg" type="revolute">
    <parent link="thigh_link"/>
    <child link="leg_link"/>
    <origin xyz="0.1246 0 -0.021 "/>
    <axis xyz="0 1 0"/>
    <limit effort="1000.0" lower="-0.785" upper="0.785" velocity="0.5"/>
  </joint>

</robot>
