<?xml version="1.0" ?>
<!-- =================================================================================== -->
<!-- |    This document was autogenerated by xacro from urdf/quadruped.xacro           | -->
<!-- |    EDITING THIS FILE BY HAND IS NOT RECOMMENDED                                 | -->
<!-- =================================================================================== -->
<robot name="quadruped" xmlns:xacro="http://www.ros.org/wiki/xacro">
  <!-- ############################################ 
       Colors
       ############################################ -->
  <material name="blue">
    <color rgba="0 0 0.8 1"/>
  </material>
  <material name="black">
    <color rgba="0 0 0 1"/>
  </material>
  <material name="white">
    <color rgba="1 1 1 1"/>
  </material>
  <!-- ############################################ 
       Macro - servo
     ############################################ -->
  <!-- ############################################ 
       Macro - leg
       ############################################ -->
  <!-- ############################################ 
       Parameters
       ############################################ -->
  <!-- ############################################ 
       Base
       ############################################ -->
  <link name="base_link">
    <visual>
      <geometry>
        <box size="0.31 0.2 0.006"/>
      </geometry>
      <origin rpy="0 0 0" xyz="0 0 0.0"/>
      <material name="white"/>
    </visual>
    <collision>
      <geometry>
        <box size="0.31 0.2 0.006"/>
      </geometry>
      <origin rpy="0 0 0" xyz="0 0 0.0"/>
    </collision>
    <inertial>
      <mass value="2"/>
      <inertia ixx="0.4" ixy="0.0" ixz="0.0" iyy="0.4" iyz="0.0" izz="0.2"/>
    </inertial>
  </link>
  <!-- ############################################ 
       leg - front left
       ############################################ -->
  <link name="front_left_hip_link">
    <visual>
      <geometry>
        <cylinder length="0.045" radius="0.0127"/>
      </geometry>
      <origin rpy="0 0 0" xyz="0 0 0.0"/>
      <material name="blue"/>
    </visual>
    <collision>
      <geometry>
        <cylinder length="0.045" radius="0.0127"/>
      </geometry>
      <origin rpy="0 0 0" xyz="0 0 0.0"/>
    </collision>
    <inertial>
      <mass value="0.03"/>
      <inertia ixx="0.4" ixy="0.0" ixz="0.0" iyy="0.4" iyz="0.0" izz="0.2"/>
    </inertial>
  </link>
  <link name="front_left_thigh_link">
    <visual>
      <geometry>
        <box size="0.15 0.035 0.006"/>
      </geometry>
      <material name="white"/>
      <origin rpy="0 0 0" xyz="0.052 0 -0.015"/>
    </visual>
    <collision>
      <geometry>
        <box size="0.15 0.035 0.006"/>
      </geometry>
      <material name="white"/>
      <origin rpy="0 0 0" xyz="0.052 0 -0.015"/>
    </collision>
    <inertial>
      <mass value="0.03"/>
      <inertia ixx="0.4" ixy="0.0" ixz="0.0" iyy="0.4" iyz="0.0" izz="0.2"/>
    </inertial>
  </link>
  <joint name="front_left_hip_to_thigh" type="revolute">
    <parent link="front_left_hip_link"/>
    <child link="front_left_thigh_link"/>
    <origin xyz="0 0 -0.0255"/>
    <axis xyz="0 1 0"/>
    <limit effort="1000.0" lower="-0.5" upper="1.5707963268" velocity="6.54498469498"/>
  </joint>
  <link name="front_left_leg_link">
    <visual>
      <geometry>
        <cylinder length="0.14" radius="0.0127"/>
      </geometry>
      <material name="white"/>
      <origin rpy="0 0 0" xyz="0 0 -0.07"/>
    </visual>
    <collision>
      <geometry>
        <cylinder length="0.14" radius="0.0127"/>
      </geometry>
      <origin rpy="0 0 0" xyz="0 0 -0.07"/>
      <contact_coefficients mu="0.8"/>
    </collision>
    <inertial>
      <mass value="0.03"/>
      <inertia ixx="0.4" ixy="0.0" ixz="0.0" iyy="0.4" iyz="0.0" izz="0.2"/>
    </inertial>
  </link>
  <joint name="front_left_thigh_to_leg" type="revolute">
    <parent link="front_left_thigh_link"/>
    <child link="front_left_leg_link"/>
    <origin xyz="0.104 0 -0.036"/>
    <axis xyz="0 1 0"/>
    <limit effort="1000.0" lower="-1.5707963268" upper="1.5707963268" velocity="6.54498469498"/>
  </joint>
  <joint name="base_front_left_joint" type="revolute">
    <parent link="base_link"/>
    <child link="front_left_hip_link"/>
    <origin xyz="0.135 0.08 -0.053"/>
    <axis xyz="1 0 0"/>
    <limit effort="1000.0" lower="-0.785" upper="0.785" velocity="6.54498469498"/>
  </joint>
  <!-- ############################################ 
       leg - front right
       ############################################ -->
  <link name="front_right_hip_link">
    <visual>
      <geometry>
        <cylinder length="0.045" radius="0.0127"/>
      </geometry>
      <origin rpy="0 0 0" xyz="0 0 0.0"/>
      <material name="blue"/>
    </visual>
    <collision>
      <geometry>
        <cylinder length="0.045" radius="0.0127"/>
      </geometry>
      <origin rpy="0 0 0" xyz="0 0 0.0"/>
    </collision>
    <inertial>
      <mass value="0.03"/>
      <inertia ixx="0.4" ixy="0.0" ixz="0.0" iyy="0.4" iyz="0.0" izz="0.2"/>
    </inertial>
  </link>
  <link name="front_right_thigh_link">
    <visual>
      <geometry>
        <box size="0.15 0.035 0.006"/>
      </geometry>
      <material name="white"/>
      <origin rpy="0 0 0" xyz="0.052 0 -0.015"/>
    </visual>
    <collision>
      <geometry>
        <box size="0.15 0.035 0.006"/>
      </geometry>
      <material name="white"/>
      <origin rpy="0 0 0" xyz="0.052 0 -0.015"/>
    </collision>
    <inertial>
      <mass value="0.03"/>
      <inertia ixx="0.4" ixy="0.0" ixz="0.0" iyy="0.4" iyz="0.0" izz="0.2"/>
    </inertial>
  </link>
  <joint name="front_right_hip_to_thigh" type="revolute">
    <parent link="front_right_hip_link"/>
    <child link="front_right_thigh_link"/>
    <origin xyz="0 0 -0.0255"/>
    <axis xyz="0 1 0"/>
    <limit effort="1000.0" lower="-0.5" upper="1.5707963268" velocity="6.54498469498"/>
  </joint>
  <link name="front_right_leg_link">
    <visual>
      <geometry>
        <cylinder length="0.14" radius="0.0127"/>
      </geometry>
      <material name="white"/>
      <origin rpy="0 0 0" xyz="0 0 -0.07"/>
    </visual>
    <collision>
      <geometry>
        <cylinder length="0.14" radius="0.0127"/>
      </geometry>
      <origin rpy="0 0 0" xyz="0 0 -0.07"/>
      <contact_coefficients mu="0.8"/>
    </collision>
    <inertial>
      <mass value="0.03"/>
      <inertia ixx="0.4" ixy="0.0" ixz="0.0" iyy="0.4" iyz="0.0" izz="0.2"/>
    </inertial>
  </link>
  <joint name="front_right_thigh_to_leg" type="revolute">
    <parent link="front_right_thigh_link"/>
    <child link="front_right_leg_link"/>
    <origin xyz="0.104 0 -0.036"/>
    <axis xyz="0 1 0"/>
    <limit effort="1000.0" lower="-1.5707963268" upper="1.5707963268" velocity="6.54498469498"/>
  </joint>
  <joint name="base_front_right_joint" type="revolute">
    <parent link="base_link"/>
    <child link="front_right_hip_link"/>
    <origin xyz="0.135 -0.08 -0.053"/>
    <axis xyz="-1 0 0"/>
    <limit effort="1000.0" lower="-0.785" upper="0.785" velocity="6.54498469498"/>
  </joint>
  <!-- ############################################ 
       leg - rear left
       ############################################ -->
  <link name="rear_left_hip_link">
    <visual>
      <geometry>
        <cylinder length="0.045" radius="0.0127"/>
      </geometry>
      <origin rpy="0 0 0" xyz="0 0 0.0"/>
      <material name="blue"/>
    </visual>
    <collision>
      <geometry>
        <cylinder length="0.045" radius="0.0127"/>
      </geometry>
      <origin rpy="0 0 0" xyz="0 0 0.0"/>
    </collision>
    <inertial>
      <mass value="0.03"/>
      <inertia ixx="0.4" ixy="0.0" ixz="0.0" iyy="0.4" iyz="0.0" izz="0.2"/>
    </inertial>
  </link>
  <link name="rear_left_thigh_link">
    <visual>
      <geometry>
        <box size="0.15 0.035 0.006"/>
      </geometry>
      <material name="white"/>
      <origin rpy="0 0 0" xyz="0.052 0 -0.015"/>
    </visual>
    <collision>
      <geometry>
        <box size="0.15 0.035 0.006"/>
      </geometry>
      <material name="white"/>
      <origin rpy="0 0 0" xyz="0.052 0 -0.015"/>
    </collision>
    <inertial>
      <mass value="0.03"/>
      <inertia ixx="0.4" ixy="0.0" ixz="0.0" iyy="0.4" iyz="0.0" izz="0.2"/>
    </inertial>
  </link>
  <joint name="rear_left_hip_to_thigh" type="revolute">
    <parent link="rear_left_hip_link"/>
    <child link="rear_left_thigh_link"/>
    <origin xyz="0 0 -0.0255"/>
    <axis xyz="0 1 0"/>
    <limit effort="1000.0" lower="-0.5" upper="1.5707963268" velocity="6.54498469498"/>
  </joint>
  <link name="rear_left_leg_link">
    <visual>
      <geometry>
        <cylinder length="0.14" radius="0.0127"/>
      </geometry>
      <material name="white"/>
      <origin rpy="0 0 0" xyz="0 0 -0.07"/>
    </visual>
    <collision>
      <geometry>
        <cylinder length="0.14" radius="0.0127"/>
      </geometry>
      <origin rpy="0 0 0" xyz="0 0 -0.07"/>
      <contact_coefficients mu="0.8"/>
    </collision>
    <inertial>
      <mass value="0.03"/>
      <inertia ixx="0.4" ixy="0.0" ixz="0.0" iyy="0.4" iyz="0.0" izz="0.2"/>
    </inertial>
  </link>
  <joint name="rear_left_thigh_to_leg" type="revolute">
    <parent link="rear_left_thigh_link"/>
    <child link="rear_left_leg_link"/>
    <origin xyz="0.104 0 -0.036"/>
    <axis xyz="0 1 0"/>
    <limit effort="1000.0" lower="-1.5707963268" upper="1.5707963268" velocity="6.54498469498"/>
  </joint>
  <joint name="base_rear_left_joint" type="revolute">
    <parent link="base_link"/>
    <child link="rear_left_hip_link"/>
    <origin xyz="-0.135 0.08 -0.053"/>
    <axis xyz="1 0 0"/>
    <limit effort="1000.0" lower="-0.785" upper="0.785" velocity="6.54498469498"/>
  </joint>
  <!-- ############################################ 
       leg - rear right
       ############################################ -->
  <link name="rear_right_hip_link">
    <visual>
      <geometry>
        <cylinder length="0.045" radius="0.0127"/>
      </geometry>
      <origin rpy="0 0 0" xyz="0 0 0.0"/>
      <material name="blue"/>
    </visual>
    <collision>
      <geometry>
        <cylinder length="0.045" radius="0.0127"/>
      </geometry>
      <origin rpy="0 0 0" xyz="0 0 0.0"/>
    </collision>
    <inertial>
      <mass value="0.03"/>
      <inertia ixx="0.4" ixy="0.0" ixz="0.0" iyy="0.4" iyz="0.0" izz="0.2"/>
    </inertial>
  </link>
  <link name="rear_right_thigh_link">
    <visual>
      <geometry>
        <box size="0.15 0.035 0.006"/>
      </geometry>
      <material name="white"/>
      <origin rpy="0 0 0" xyz="0.052 0 -0.015"/>
    </visual>
    <collision>
      <geometry>
        <box size="0.15 0.035 0.006"/>
      </geometry>
      <material name="white"/>
      <origin rpy="0 0 0" xyz="0.052 0 -0.015"/>
    </collision>
    <inertial>
      <mass value="0.03"/>
      <inertia ixx="0.4" ixy="0.0" ixz="0.0" iyy="0.4" iyz="0.0" izz="0.2"/>
    </inertial>
  </link>
  <joint name="rear_right_hip_to_thigh" type="revolute">
    <parent link="rear_right_hip_link"/>
    <child link="rear_right_thigh_link"/>
    <origin xyz="0 0 -0.0255"/>
    <axis xyz="0 1 0"/>
    <limit effort="1000.0" lower="-0.5" upper="1.5707963268" velocity="6.54498469498"/>
  </joint>
  <link name="rear_right_leg_link">
    <visual>
      <geometry>
        <cylinder length="0.14" radius="0.0127"/>
      </geometry>
      <material name="white"/>
      <origin rpy="0 0 0" xyz="0 0 -0.07"/>
    </visual>
    <collision>
      <geometry>
        <cylinder length="0.14" radius="0.0127"/>
      </geometry>
      <origin rpy="0 0 0" xyz="0 0 -0.07"/>
      <contact_coefficients mu="0.8"/>
    </collision>
    <inertial>
      <mass value="0.03"/>
      <inertia ixx="0.4" ixy="0.0" ixz="0.0" iyy="0.4" iyz="0.0" izz="0.2"/>
    </inertial>
  </link>
  <joint name="rear_right_thigh_to_leg" type="revolute">
    <parent link="rear_right_thigh_link"/>
    <child link="rear_right_leg_link"/>
    <origin xyz="0.104 0 -0.036"/>
    <axis xyz="0 1 0"/>
    <limit effort="1000.0" lower="-1.5707963268" upper="1.5707963268" velocity="6.54498469498"/>
  </joint>
  <joint name="base_rear_right_joint" type="revolute">
    <parent link="base_link"/>
    <child link="rear_right_hip_link"/>
    <origin xyz="-0.135 -0.08 -0.053"/>
    <axis xyz="-1 0 0"/>
    <limit effort="1000.0" lower="-0.785" upper="0.785" velocity="6.54498469498"/>
  </joint>
</robot>

